Workbook
Name Slicer_Channel: #N/A
Name Slicer_Country: #N/A
Name Slicer_DiscountPct: #N/A
Name Slicer_Gross_Profit: #N/A
Name Slicer_Gross_Revenue: #N/A
Name Slicer_Leadtime_days: #N/A
Name Slicer_Month: #N/A
Name Slicer_OrderID: #N/A
Name Slicer_ProductCategory: #N/A
Name Slicer_Region: #N/A
Name Slicer_Salesperson: #N/A
Name Slicer_SKU: #N/A

Sheet Data
A1: ORD-2024-275203 | B1: 45362 | C1: 45388 | D1: =DATEDIF(B1,C1, "MD") -> 26 | E1: =TEXT(Data!B1,"MMM-YYYY") -> Mar-2024 | F1: ="Q"&ROUNDUP(MONTH(B1)/3,0)&"-"&YEAR(B1) -> Q1-2024 | G1: Africa | H1: Kenya | I1: Kisumu | J1: Corporate | K1: Retail | L1: C. Otieno | M1: Components | N1: CMP-8270 | O1: 279.24 | P1: =IF(Q1<50, "Low", IF(Q1<200, "Medium", "High")) -> High | Q1: 608.9 | R1: 0.112 | S1: 9 | T1: =(Q27*S1)*(1-R1) -> 1403.9546 | U1: =(O1*S1) -> 2513.16 | V1: =(T1-U1) -> -1109.2054 | W1: =IF(T1=0, 0, V1/T1) -> -0.79005783
A2: ORD-2024-358795 | B2: 45588 | C2: 45587 | D2: =DATEDIF(C2, B2, "MD") -> 1 | E2: =TEXT(Data!B2,"MMM-YYYY") -> Oct-2024 | F2: ="Q"&ROUNDUP(MONTH(B2)/3,0)&"-"&YEAR(B2) -> Q4-2024 | G2: Africa | H2: Nigeria | I2: Port Harcourt | J2: Education | K2: Online | L2: J. Njeri | M2: Printers | N2: PRN-9322 | O2: 1084.39 | P2: =IF(Q2<50, "Low", IF(Q2<200, "Medium", "High")) -> High | Q2: 759.33 | R2: 0.237 | S2: 31 | T2: =(Q28*S2)*(1-R2) -> 17934.414 | U2: =(O2*S2) -> 33616.09 | V2: =(T2-U2) -> -15681.676 | W2: =IF(T2=0, 0, V2/T2) -> -0.87439019
A3: ORD-2023-373538 | B3: 44985 | C3: 45010 | D3: =DATEDIF(B3,C3, "MD") -> 25 | E3: =TEXT(Data!B3,"MMM-YYYY") -> Feb-2023 | F3: ="Q"&ROUNDUP(MONTH(B3)/3,0)&"-"&YEAR(B3) -> Q1-2023 | G3: Africa | H3: Kenya | I3: Nairobi | J3: Corporate | K3: Retail | L3: I. Johnson | M3: Networking | N3: NET-9666 | O3: 1460.76 | P3: =IF(Q3<50, "Low", IF(Q3<200, "Medium", "High")) -> Low | Q3: -30.66 | R3: 0.131 | S3: 12 | T3: =(Q29*S3)*(1-R3) -> 4534.0944 | U3: =(O3*S3) -> 17529.12 | V3: =(T3-U3) -> -12995.026 | W3: =IF(T3=0, 0, V3/T3) -> -2.8660686
A4: ORD-2025-168148 | B4: 45745 | C4: 45749 | D4: =DATEDIF(B4,C4, "MD") -> 4 | E4: =TEXT(Data!B4,"MMM-YYYY") -> Mar-2025 | F4: ="Q"&ROUNDUP(MONTH(B4)/3,0)&"-"&YEAR(B4) -> Q1-2025 | G4: Africa | H4: Nigeria | I4: Lagos | J4: Non-Profit | K4: Marketplace | L4: G. Dubois | M4: Phones | N4: PHN-4556 | O4: 259.93 | P4: =IF(Q4<50, "Low", IF(Q4<200, "Medium", "High")) -> High | Q4: 255.94 | R4: 0.072 | S4: 22 | T4: =(Q30*S4)*(1-R4) -> 34016.731 | U4: =(O4*S4) -> 5718.46 | V4: =(T4-U4) -> 28298.271 | W4: =IF(T4=0, 0, V4/T4) -> 0.83189272
A5: ORD-2023-824839 | B5: 45266 | C5: 45291 | D5: =DATEDIF(B5,C5, "MD") -> 25 | E5: =TEXT(Data!B5,"MMM-YYYY") -> Dec-2023 | F5: ="Q"&ROUNDUP(MONTH(B5)/3,0)&"-"&YEAR(B5) -> Q4-2023 | G5: Asia | H5: Japan | I5: Osaka | J5: Consumer | K5: Retail | L5: L. Okafor | M5: Printers | N5: PRN-8041 | O5: 663.03 | P5: =IF(Q5<50, "Low", IF(Q5<200, "Medium", "High")) -> High | Q5: 813.51 | R5: 0.102 | S5: 15 | T5: =(Q31*S5)*(1-R5) -> 8510.0766 | U5: =(O5*S5) -> 9945.45 | V5: =(T5-U5) -> -1435.3734 | W5: =IF(T5=0, 0, V5/T5) -> -0.16866751
A6: ORD-2023-723587 | B6: 44928 | C6: 44931 | D6: =DATEDIF(B6,C6, "MD") -> 3 | E6: =TEXT(Data!B6,"MMM-YYYY") -> Jan-2023 | F6: ="Q"&ROUNDUP(MONTH(B6)/3,0)&"-"&YEAR(B6) -> Q1-2023 | G6: Americas | H6: Canada | I6: Toronto | J6: Corporate | K6: Distributor | L6: B. Chen | M6: Laptops | N6: LAP-8555 | O6: 315.87 | P6: =IF(Q6<50, "Low", IF(Q6<200, "Medium", "High")) -> High | Q6: 591.68 | R6: 0 | S6: 7 | T6: =(Q32*S6)*(1-R6) -> 12558.49 | U6: =(O6*S6) -> 2211.09 | V6: =(T6-U6) -> 10347.4 | W6: =IF(T6=0, 0, V6/T6) -> 0.82393664
A7: ORD-2024-336584 | B7: 45653 | C7: 45671 | D7: =DATEDIF(B7,C7, "MD") -> 18 | E7: =TEXT(Data!B7,"MMM-YYYY") -> Dec-2024 | F7: ="Q"&ROUNDUP(MONTH(B7)/3,0)&"-"&YEAR(B7) -> Q4-2024 | G7: Asia | H7: India | I7: Bengaluru | J7: Small Business | K7: Marketplace | L7: E. Garcia | M7: Monitors | N7: MON-8629 | O7: 586.07 | P7: =IF(Q7<50, "Low", IF(Q7<200, "Medium", "High")) -> High | Q7: 845.97 | R7: 0.147 | S7: 4 | T7: =(Q33*S7)*(1-R7) -> 8983.8642 | U7: =(O7*S7) -> 2344.28 | V7: =(T7-U7) -> 6639.5842 | W7: =IF(T7=0, 0, V7/T7) -> 0.73905661
A8: ORD-2023-112666 | B8: 44941 | C8: 44939 | D8: =DATEDIF(C8,B8, "MD") -> 2 | E8: =TEXT(Data!B8,"MMM-YYYY") -> Jan-2023 | F8: ="Q"&ROUNDUP(MONTH(B8)/3,0)&"-"&YEAR(B8) -> Q1-2023 | G8: Africa | H8: Nigeria | I8: Abuja | J8: Education | K8: Online | L8: O. Wang | M8: Printers | N8: PRN-6276 | O8: 28.38 | P8: =IF(Q8<50, "Low", IF(Q8<200, "Medium", "High")) -> Low | Q8: 47.22 | R8: 0.194 | S8: 18 | T8: =(Q34*S8)*(1-R8) -> 19177.4 | U8: =(O8*S8) -> 510.84 | V8: =(T8-U8) -> 18666.56 | W8: =IF(T8=0, 0, V8/T8) -> 0.9733624
A9: ORD-2024-589570 | B9: 45416 | C9: 45441 | D9: =DATEDIF(B9,C9, "MD") -> 25 | E9: =TEXT(Data!B9,"MMM-YYYY") -> May-2024 | F9: ="Q"&ROUNDUP(MONTH(B9)/3,0)&"-"&YEAR(B9) -> Q2-2024 | G9: Africa | H9: Nigeria | I9: Abuja | J9: Non-Profit | K9: Marketplace | L9: O. Wang | M9: Monitors | N9: MON-6892 | O9: 1295.34 | P9: =IF(Q9<50, "Low", IF(Q9<200, "Medium", "High")) -> High | Q9: 2530.81 | R9: 0.031 | S9: 6 | T9: =(Q35*S9)*(1-R9) -> 17656.362 | U9: =(O9*S9) -> 7772.04 | V9: =(T9-U9) -> 9884.3222 | W9: =IF(T9=0, 0, V9/T9) -> 0.55981646
A10: ORD-2025-997421 | B10: 45798 | C10: 45817 | D10: =DATEDIF(B10,C10, "MD") -> 19 | E10: =TEXT(Data!B10,"MMM-YYYY") -> May-2025 | F10: ="Q"&ROUNDUP(MONTH(B10)/3,0)&"-"&YEAR(B10) -> Q2-2025 | G10: Americas | H10: Brazil | I10: São Paulo | J10: Non-Profit | K10: Online | L10: A. Patel | M10: Components | N10: CMP-3731 | O10: 1331.38 | P10: =IF(Q10<50, "Low", IF(Q10<200, "Medium", "High")) -> High | Q10: 2309.56 | R10: 0.149 | S10: 31 | T10: =(Q36*S10)*(1-R10) -> 5259.58 | U10: =(O10*S10) -> 41272.78 | V10: =(T10-U10) -> -36013.2 | W10: =IF(T10=0, 0, V10/T10) -> -6.8471627
A11: ORD-2024-210687 | B11: 45319 | C11: 45331 | D11: =DATEDIF(B11,C11, "MD") -> 12 | E11: =TEXT(Data!B11,"MMM-YYYY") -> Jan-2024 | F11: ="Q"&ROUNDUP(MONTH(B11)/3,0)&"-"&YEAR(B11) -> Q1-2024 | G11: Europe | H11: Germany | I11: Berlin | J11: Corporate | K11: Online | L11: G. Dubois | M11: Accessories | N11: ACC-7938 | O11: 644.17 | P11: =IF(Q11<50, "Low", IF(Q11<200, "Medium", "High")) -> High | Q11: 700.12 | R11: 0.006 | S11: 23 | T11: =(Q37*S11)*(1-R11) -> 21204.734 | U11: =(O11*S11) -> 14815.91 | V11: =(T11-U11) -> 6388.8236 | W11: =IF(T11=0, 0, V11/T11) -> 0.30129233
A12: ORD-2025-515515 | B12: 45660 | C12: 45680 | D12: =DATEDIF(B12,C12, "MD") -> 20 | E12: =TEXT(Data!B12,"MMM-YYYY") -> Jan-2025 | F12: ="Q"&ROUNDUP(MONTH(B12)/3,0)&"-"&YEAR(B12) -> Q1-2025 | G12: Asia | H12: Japan | I12: Osaka | J12: Corporate | K12: Distributor | L12: F. Müller | M12: Phones | N12: PHN-7019 | O12: 908.6 | P12: =IF(Q12<50, "Low", IF(Q12<200, "Medium", "High")) -> High | Q12: 691.37 | R12: 0.25 | S12: 20 | T12: =(Q38*S12)*(1-R12) -> 26031.15 | U12: =(O12*S12) -> 18172 | V12: =(T12-U12) -> 7859.15 | W12: =IF(T12=0, 0, V12/T12) -> 0.30191328
A13: ORD-2025-487261 | B13: 45722 | C13: 45747 | D13: =DATEDIF(B13,C13, "MD") -> 25 | E13: =TEXT(Data!B13,"MMM-YYYY") -> Mar-2025 | F13: ="Q"&ROUNDUP(MONTH(B13)/3,0)&"-"&YEAR(B13) -> Q1-2025 | G13: Americas | H13: Brazil | I13: Brasília | J13: Non-Profit | K13: Online | L13: J. Njeri | M13: Components | N13: CMP-3693 | O13: 331.57 | P13: =IF(Q13<50, "Low", IF(Q13<200, "Medium", "High")) -> High | Q13: 548.4 | R13: 0.094 | S13: 10 | T13: =(Q39*S13)*(1-R13) -> 12644.498 | U13: =(O13*S13) -> 3315.7 | V13: =(T13-U13) -> 9328.7984 | W13: =IF(T13=0, 0, V13/T13) -> 0.73777528
A14: ORD-2024-890180 | B14: 45311 | C14: 45335 | D14: =DATEDIF(B14,C14, "MD") -> 24 | E14: =TEXT(Data!B14,"MMM-YYYY") -> Jan-2024 | F14: ="Q"&ROUNDUP(MONTH(B14)/3,0)&"-"&YEAR(B14) -> Q1-2024 | G14: Europe | H14: France | I14: Marseille | J14: Corporate | K14: Retail | L14: H. Kim | M14: Printers | N14: PRN-8392 | O14: 643.53 | P14: =IF(Q14<50, "Low", IF(Q14<200, "Medium", "High")) -> High | Q14: 1439.01 | R14: 0 | S14: 15 | T14: =(Q40*S14)*(1-R14) -> 6816.3 | U14: =(O14*S14) -> 9652.95 | V14: =(T14-U14) -> -2836.65 | W14: =IF(T14=0, 0, V14/T14) -> -0.41615686
A15: ORD-2025-840976 | B15: 45901 | C15: 45930 | D15: =DATEDIF(B15,C15, "MD") -> 29 | E15: =TEXT(Data!B15,"MMM-YYYY") -> Sept-2025 | F15: ="Q"&ROUNDUP(MONTH(B15)/3,0)&"-"&YEAR(B15) -> Q3-2025 | G15: Americas | H15: Brazil | I15: Brasília | J15: Education | K15: Retail | L15: K. Singh | M15: Accessories | N15: ACC-1663 | O15: 780.59 | P15: =IF(Q15<50, "Low", IF(Q15<200, "Medium", "High")) -> High | Q15: 631.57 | R15: 0 | S15: 12 | T15: =(Q41*S15)*(1-R15) -> 18971.64 | U15: =(O15*S15) -> 9367.08 | V15: =(T15-U15) -> 9604.56 | W15: =IF(T15=0, 0, V15/T15) -> 0.50625882
A16: ORD-2023-937291 | B16: 45039 | C16: 45038 | D16: =DATEDIF(C16, B16, "MD") -> 1 | E16: =TEXT(Data!B16,"MMM-YYYY") -> Apr-2023 | F16: ="Q"&ROUNDUP(MONTH(B16)/3,0)&"-"&YEAR(B16) -> Q2-2023 | G16: Africa | H16: Kenya | I16: Nairobi | J16: Small Business | K16: Direct | L16: E. Garcia | M16: Laptops | N16: LAP-1698 | O16: 756.51 | P16: =IF(Q16<50, "Low", IF(Q16<200, "Medium", "High")) -> High | Q16: 850.8 | R16: 0.074 | S16: 9 | T16: =(Q42*S16)*(1-R16) -> 14666.09 | U16: =(O16*S16) -> 6808.59 | V16: =(T16-U16) -> 7857.4999 | W16: =IF(T16=0, 0, V16/T16) -> 0.5357597
A17: ORD-2024-206081 | B17: 45636 | C17: 45665 | D17: =DATEDIF(B17,C17, "MD") -> 29 | E17: =TEXT(Data!B17,"MMM-YYYY") -> Dec-2024 | F17: ="Q"&ROUNDUP(MONTH(B17)/3,0)&"-"&YEAR(B17) -> Q4-2024 | G17: Europe | H17: France | I17: Marseille | J17: Small Business | K17: Retail | L17: K. Singh | M17: Printers | N17: PRN-6791 | O17: 891.08 | P17: =IF(Q17<50, "Low", IF(Q17<200, "Medium", "High")) -> High | Q17: 1040.1 | R17: 0.109 | S17: 28 | T17: =(Q43*S17)*(1-R17) -> 79945.866 | U17: =(O17*S17) -> 24950.24 | V17: =(T17-U17) -> 54995.626 | W17: =IF(T17=0, 0, V17/T17) -> 0.68791082
A18: ORD-2025-233883 | B18: 45908 | C18: 45916 | D18: =DATEDIF(B18,C18, "MD") -> 8 | E18: =TEXT(Data!B18,"MMM-YYYY") -> Sept-2025 | F18: ="Q"&ROUNDUP(MONTH(B18)/3,0)&"-"&YEAR(B18) -> Q3-2025 | G18: Asia | H18: Japan | I18: Osaka | J18: Corporate | K18: Distributor | L18: C. Otieno | M18: Phones | N18: PHN-1197 | O18: 1225.57 | P18: =IF(Q18<50, "Low", IF(Q18<200, "Medium", "High")) -> High | Q18: 2705.57 | R18: 0.183 | S18: 16 | T18: =(Q44*S18)*(1-R18) -> 14842.341 | U18: =(O18*S18) -> 19609.12 | V18: =(T18-U18) -> -4766.779 | W18: =IF(T18=0, 0, V18/T18) -> -0.32116086
A19: ORD-2025-843974 | B19: 45858 | C19: 45874 | D19: =DATEDIF(B19,C19, "MD") -> 16 | E19: =TEXT(Data!B19,"MMM-YYYY") -> Jul-2025 | F19: ="Q"&ROUNDUP(MONTH(B19)/3,0)&"-"&YEAR(B19) -> Q3-2025 | G19: Americas | H19: Brazil | I19: Brasília | J19: Enterprise | K19: Marketplace | L19: G. Dubois | M19: Accessories | N19: ACC-8098 | O19: 1068.17 | P19: =IF(Q19<50, "Low", IF(Q19<200, "Medium", "High")) -> High | Q19: 2375.37 | R19: 0.109 | S19: 18 | T19: =(Q45*S19)*(1-R19) -> 15979.622 | U19: =(O19*S19) -> 19227.06 | V19: =(T19-U19) -> -3247.4383 | W19: =IF(T19=0, 0, V19/T19) -> -0.20322373
A20: ORD-2025-745263 | B20: 45798 | C20: 45796 | D20: =DATEDIF(C20,B20, "MD") -> 2 | E20: =TEXT(Data!B20,"MMM-YYYY") -> May-2025 | F20: ="Q"&ROUNDUP(MONTH(B20)/3,0)&"-"&YEAR(B20) -> Q2-2025 | G20: Europe | H20: United Kingdom | I20: Birmingham | J20: Enterprise | K20: Online | L20: M. Rossi | M20: Laptops | N20: LAP-3385 | O20: 1015.16 | P20: =IF(Q20<50, "Low", IF(Q20<200, "Medium", "High")) -> High | Q20: 2148.14 | R20: 0.038 | S20: 19 | T20: =(Q46*S20)*(1-R20) -> 25535.28 | U20: =(O20*S20) -> 19288.04 | V20: =(T20-U20) -> 6247.2399 | W20: =IF(T20=0, 0, V20/T20) -> 0.24465132
A21: ORD-2024-798002 | B21: 45498 | C21: 45497 | D21: =DATEDIF(C21,B21, "MD") -> 1 | E21: =TEXT(Data!B21,"MMM-YYYY") -> Jul-2024 | F21: ="Q"&ROUNDUP(MONTH(B21)/3,0)&"-"&YEAR(B21) -> Q3-2024 | G21: Africa | H21: Kenya | I21: Mombasa | J21: Non-Profit | K21: Direct | L21: J. Njeri | M21: Laptops | N21: LAP-9815 | O21: 1494.4 | P21: =IF(Q21<50, "Low", IF(Q21<200, "Medium", "High")) -> High | Q21: 3661.07 | R21: 0.072 | S21: 7 | T21: =(Q47*S21)*(1-R21) -> 3565.5894 | U21: =(O21*S21) -> 10460.8 | V21: =(T21-U21) -> -6895.2106 | W21: =IF(T21=0, 0, V21/T21) -> -1.9338207
A22: ORD-2023-867836 | B22: 45057 | C22: 45074 | D22: =DATEDIF(B22,C22, "MD") -> 17 | E22: =TEXT(Data!B22,"MMM-YYYY") -> May-2023 | F22: ="Q"&ROUNDUP(MONTH(B22)/3,0)&"-"&YEAR(B22) -> Q2-2023 | G22: Asia | H22: China | I22: Shenzhen | J22: Enterprise | K22: Marketplace | L22: E. Garcia | M22: Networking | N22: NET-3255 | O22: 1331.19 | P22: =IF(Q22<50, "Low", IF(Q22<200, "Medium", "High")) -> High | Q22: 2903.09 | R22: 0.143 | S22: 8 | T22: =(Q48*S22)*(1-R22) -> 24160.544 | U22: =(O22*S22) -> 10649.52 | V22: =(T22-U22) -> 13511.024 | W22: =IF(T22=0, 0, V22/T22) -> 0.55921853
A23: ORD-2025-580047 | B23: 45822 | C23: 45837 | D23: =DATEDIF(B23,C23, "MD") -> 15 | E23: =TEXT(Data!B23,"MMM-YYYY") -> Jun-2025 | F23: ="Q"&ROUNDUP(MONTH(B23)/3,0)&"-"&YEAR(B23) -> Q2-2025 | G23: Africa | H23: Nigeria | I23: Port Harcourt | J23: Consumer | K23: Marketplace | L23: M. Rossi | M23: Accessories | N23: ACC-3961 | O23: 730.99 | P23: =IF(Q23<50, "Low", IF(Q23<200, "Medium", "High")) -> High | Q23: 1242.84 | R23: 0.12 | S23: 10 | T23: =(Q49*S23)*(1-R23) -> 16065.368 | U23: =(O23*S23) -> 7309.9 | V23: =(T23-U23) -> 8755.468 | W23: =IF(T23=0, 0, V23/T23) -> 0.54499019
A24: ORD-2024-500109 | B24: 45430 | C24: 45435 | D24: =DATEDIF(B24,C24, "MD") -> 5 | E24: =TEXT(Data!B24,"MMM-YYYY") -> May-2024 | F24: ="Q"&ROUNDUP(MONTH(B24)/3,0)&"-"&YEAR(B24) -> Q2-2024 | G24: Americas | H24: USA | I24: Chicago | J24: Enterprise | K24: Retail | L24: H. Kim | M24: Laptops | N24: LAP-4987 | O24: 1274.59 | P24: =IF(Q24<50, "Low", IF(Q24<200, "Medium", "High")) -> High | Q24: 2553.69 | R24: 0.01 | S24: 8 | T24: =(Q50*S24)*(1-R24) -> 14187.65 | U24: =(O24*S24) -> 10196.72 | V24: =(T24-U24) -> 3990.9304 | W24: =IF(T24=0, 0, V24/T24) -> 0.28129608
A25: ORD-2023-271836 | B25: 44964 | C25: 44969 | D25: =DATEDIF(B25,C25, "MD") -> 5 | E25: =TEXT(Data!B25,"MMM-YYYY") -> Feb-2023 | F25: ="Q"&ROUNDUP(MONTH(B25)/3,0)&"-"&YEAR(B25) -> Q1-2023 | G25: Americas | H25: Brazil | I25: São Paulo | J25: Education | K25: Online | L25: N. Brown | M25: Components | N25: CMP-2693 | O25: 948.55 | P25: =IF(Q25<50, "Low", IF(Q25<200, "Medium", "High")) -> High | Q25: 2089.16 | R25: 0.007 | S25: 12 | T25: =(Q51*S25)*(1-R25) -> 31336.101 | U25: =(O25*S25) -> 11382.6 | V25: =(T25-U25) -> 19953.501 | W25: =IF(T25=0, 0, V25/T25) -> 0.63675762
A26: ORD-2024-215294 | B26: 45473 | C26: 45487 | D26: =DATEDIF(B26,C26, "MD") -> 14 | E26: =TEXT(Data!B26,"MMM-YYYY") -> Jun-2024 | F26: ="Q"&ROUNDUP(MONTH(B26)/3,0)&"-"&YEAR(B26) -> Q2-2024 | G26: Americas | H26: Brazil | I26: Brasília | J26: Education | K26: Retail | L26: C. Otieno | M26: Accessories | N26: ACC-8683 | O26: 1491.85 | P26: =IF(Q26<50, "Low", IF(Q26<200, "Medium", "High")) -> High | Q26: 2583.02 | R26: 0.168 | S26: 4 | T26: =(Q52*S26)*(1-R26) -> 353.7664 | U26: =(O26*S26) -> 5967.4 | V26: =(T26-U26) -> -5613.6336 | W26: =IF(T26=0, 0, V26/T26) -> -15.868193
A27: ORD-2024-788105 | B27: 45626 | C27: 45656 | D27: =DATEDIF(B27,C27, "MD") -> 0 | E27: =TEXT(Data!B27,"MMM-YYYY") -> Nov-2024 | F27: ="Q"&ROUNDUP(MONTH(B27)/3,0)&"-"&YEAR(B27) -> Q4-2024 | G27: Europe | H27: France | I27: Marseille | J27: Consumer | K27: Marketplace | L27: F. Müller | M27: Printers | N27: PRN-4170 | O27: 117.64 | P27: =IF(Q27<50, "Low", IF(Q27<200, "Medium", "High")) -> Medium | Q27: 175.67 | R27: 0 | S27: 10 | T27: =(Q53*S27)*(1-R27) -> 3857.2 | U27: =(O27*S27) -> 1176.4 | V27: =(T27-U27) -> 2680.8 | W27: =IF(T27=0, 0, V27/T27) -> 0.69501193
A28: ORD-2024-855073 | B28: 45492 | C28: 45492 | D28: =DATEDIF(B28,C28, "MD") -> 0 | E28: =TEXT(Data!B28,"MMM-YYYY") -> Jul-2024 | F28: ="Q"&ROUNDUP(MONTH(B28)/3,0)&"-"&YEAR(B28) -> Q3-2024 | G28: Africa | H28: Kenya | I28: Kisumu | J28: Small Business | K28: Retail | L28: A. Patel | M28: Phones | N28: PHN-6854 | O28: 857.24 | P28: =IF(Q28<50, "Low", IF(Q28<200, "Medium", "High")) -> High | Q28: 758.23 | R28: 0.125 | S28: 6 | T28: =(Q54*S28)*(1-R28) -> 1243.5675 | U28: =(O28*S28) -> 5143.44 | V28: =(T28-U28) -> -3899.8725 | W28: =IF(T28=0, 0, V28/T28) -> -3.136036
A29: ORD-2023-897079 | B29: 45030 | C29: 45060 | D29: =DATEDIF(B29,C29, "MD") -> 0 | E29: =TEXT(Data!B29,"MMM-YYYY") -> Apr-2023 | F29: ="Q"&ROUNDUP(MONTH(B29)/3,0)&"-"&YEAR(B29) -> Q2-2023 | G29: Africa | H29: Kenya | I29: Nakuru | J29: Consumer | K29: Marketplace | L29: M. Rossi | M29: Phones | N29: PHN-1784 | O29: 209.25 | P29: =IF(Q29<50, "Low", IF(Q29<200, "Medium", "High")) -> High | Q29: 434.8 | R29: 0 | S29: 9 | T29: =(Q55*S29)*(1-R29) -> 377.1 | U29: =(O29*S29) -> 1883.25 | V29: =(T29-U29) -> -1506.15 | W29: =IF(T29=0, 0, V29/T29) -> -3.9940334
A30: ORD-2025-548982 | B30: 45754 | C30: 45758 | D30: =DATEDIF(B30,C30, "MD") -> 4 | E30: =TEXT(Data!B30,"MMM-YYYY") -> Apr-2025 | F30: ="Q"&ROUNDUP(MONTH(B30)/3,0)&"-"&YEAR(B30) -> Q2-2025 | G30: Europe | H30: France | I30: Lyon | J30: Education | K30: Retail | L30: E. Garcia | M30: Networking | N30: NET-9716 | O30: 754.77 | P30: =IF(Q30<50, "Low", IF(Q30<200, "Medium", "High")) -> High | Q30: 1666.18 | R30: 0.139 | S30: 14 | T30: =(Q56*S30)*(1-R30) -> 11781.339 | U30: =(O30*S30) -> 10566.78 | V30: =(T30-U30) -> 1214.5585 | W30: =IF(T30=0, 0, V30/T30) -> 0.10309173
A31: ORD-2024-170313 | B31: 45653 | C31: 45672 | D31: =DATEDIF(B31,C31, "MD") -> 19 | E31: =TEXT(Data!B31,"MMM-YYYY") -> Dec-2024 | F31: ="Q"&ROUNDUP(MONTH(B31)/3,0)&"-"&YEAR(B31) -> Q4-2024 | G31: Asia | H31: India | I31: Delhi | J31: Non-Profit | K31: Distributor | L31: G. Dubois | M31: Components | N31: CMP-6919 | O31: 495.59 | P31: =IF(Q31<50, "Low", IF(Q31<200, "Medium", "High")) -> High | Q31: 631.78 | R31: 0.087 | S31: 17 | T31: =(Q57*S31)*(1-R31) -> 43367.692 | U31: =(O31*S31) -> 8425.03 | V31: =(T31-U31) -> 34942.662 | W31: =IF(T31=0, 0, V31/T31) -> 0.80573026
A32: ORD-2023-562894 | B32: 44980 | C32: 45010 | D32: =DATEDIF(B32,C32, "MD") -> 2 | E32: =TEXT(Data!B32,"MMM-YYYY") -> Feb-2023 | F32: ="Q"&ROUNDUP(MONTH(B32)/3,0)&"-"&YEAR(B32) -> Q1-2023 | G32: Americas | H32: Canada | I32: Montreal | J32: Enterprise | K32: Online | L32: D. Smith | M32: Phones | N32: PHN-4854 | O32: 1242.66 | P32: =IF(Q32<50, "Low", IF(Q32<200, "Medium", "High")) -> High | Q32: 1794.07 | R32: 0.089 | S32: 16 | T32: =(Q58*S32)*(1-R32) -> 10231.623 | U32: =(O32*S32) -> 19882.56 | V32: =(T32-U32) -> -9650.9368 | W32: =IF(T32=0, 0, V32/T32) -> -0.94324592
A33: ORD-2025-474710 | B33: 45862 | C33: 45875 | D33: =DATEDIF(B33,C33, "MD") -> 13 | E33: =TEXT(Data!B33,"MMM-YYYY") -> Jul-2025 | F33: ="Q"&ROUNDUP(MONTH(B33)/3,0)&"-"&YEAR(B33) -> Q3-2025 | G33: Africa | H33: South Africa | I33: Johannesburg | J33: Education | K33: Marketplace | L33: D. Smith | M33: Networking | N33: NET-7966 | O33: 1463.9 | P33: =IF(Q33<50, "Low", IF(Q33<200, "Medium", "High")) -> High | Q33: 2633.02 | R33: 0.084 | S33: 4 | T33: =(Q59*S33)*(1-R33) -> -19.30928 | U33: =(O33*S33) -> 5855.6 | V33: =(T33-U33) -> -5874.9093 | W33: =IF(T33=0, 0, V33/T33) -> 304.25315
A34: ORD-2024-629525 | B34: 45400 | C34: 45420 | D34: =DATEDIF(B34,C34, "MD") -> 20 | E34: =TEXT(Data!B34,"MMM-YYYY") -> Apr-2024 | F34: ="Q"&ROUNDUP(MONTH(B34)/3,0)&"-"&YEAR(B34) -> Q2-2024 | G34: Europe | H34: United Kingdom | I34: London | J34: Non-Profit | K34: Not Provided | L34: D. Smith | M34: Laptops | N34: LAP-9932 | O34: 645.33 | P34: =IF(Q34<50, "Low", IF(Q34<200, "Medium", "High")) -> High | Q34: 1321.85 | R34: 0 | S34: 10 | T34: =(Q60*S34)*(1-R34) -> 14370.6 | U34: =(O34*S34) -> 6453.3 | V34: =(T34-U34) -> 7917.3 | W34: =IF(T34=0, 0, V34/T34) -> 0.55093733
A35: ORD-2024-167215 | B35: 45527 | C35: 45525 | D35: =DATEDIF(C35,B35, "MD") -> 2 | E35: =TEXT(Data!B35,"MMM-YYYY") -> Aug-2024 | F35: ="Q"&ROUNDUP(MONTH(B35)/3,0)&"-"&YEAR(B35) -> Q3-2024 | G35: Africa | H35: South Africa | I35: Johannesburg | J35: Education | K35: Retail | L35: E. Garcia | M35: Components | N35: CMP-1559 | O35: 1432.52 | P35: =IF(Q35<50, "Low", IF(Q35<200, "Medium", "High")) -> High | Q35: 3036.87 | R35: 0 | S35: 9 | T35: =(Q61*S35)*(1-R35) -> 17207.01 | U35: =(O35*S35) -> 12892.68 | V35: =(T35-U35) -> 4314.33 | W35: =IF(T35=0, 0, V35/T35) -> 0.25073095
A36: ORD-2023-864121 | B36: 45012 | C36: 45038 | D36: =DATEDIF(B36,C36, "MD") -> 26 | E36: =TEXT(Data!B36,"MMM-YYYY") -> Mar-2023 | F36: ="Q"&ROUNDUP(MONTH(B36)/3,0)&"-"&YEAR(B36) -> Q1-2023 | G36: Asia | H36: India | I36: Delhi | J36: Non-Profit | K36: Marketplace | L36: J. Njeri | M36: Printers | N36: PRN-4506 | O36: 178.53 | P36: =IF(Q36<50, "Low", IF(Q36<200, "Medium", "High")) -> Medium | Q36: 199.37 | R36: 0.101 | S36: 37 | T36: =(Q62*S36)*(1-R36) -> 86276.904 | U36: =(O36*S36) -> 6605.61 | V36: =(T36-U36) -> 79671.294 | W36: =IF(T36=0, 0, V36/T36) -> 0.9234371
A37: ORD-2024-692673 | B37: 45358 | C37: 45376 | D37: =DATEDIF(B37,C37, "MD") -> 18 | E37: =TEXT(Data!B37,"MMM-YYYY") -> Mar-2024 | F37: ="Q"&ROUNDUP(MONTH(B37)/3,0)&"-"&YEAR(B37) -> Q1-2024 | G37: Europe | H37: Germany | I37: Munich | J37: Corporate | K37: Online | L37: B. Chen | M37: Components | N37: CMP-7617 | O37: 712.84 | P37: =IF(Q37<50, "Low", IF(Q37<200, "Medium", "High")) -> High | Q37: 927.51 | R37: 0.243 | S37: 27 | T37: =(Q63*S37)*(1-R37) -> 25427.751 | U37: =(O37*S37) -> 19246.68 | V37: =(T37-U37) -> 6181.0711 | W37: =IF(T37=0, 0, V37/T37) -> 0.24308367
A38: ORD-2025-718992 | B38: 45832 | C38: 45848 | D38: =DATEDIF(B38,C38, "MD") -> 16 | E38: =TEXT(Data!B38,"MMM-YYYY") -> Jun-2025 | F38: ="Q"&ROUNDUP(MONTH(B38)/3,0)&"-"&YEAR(B38) -> Q2-2025 | G38: Asia | H38: China | I38: Shanghai | J38: Enterprise | K38: Direct | L38: N. Brown | M38: Components | N38: CMP-8390 | O38: 757.19 | P38: =IF(Q38<50, "Low", IF(Q38<200, "Medium", "High")) -> High | Q38: 1735.41 | R38: 0.136 | S38: 8 | T38: =(Q64*S38)*(1-R38) -> 13219.269 | U38: =(O38*S38) -> 6057.52 | V38: =(T38-U38) -> 7161.7491 | W38: =IF(T38=0, 0, V38/T38) -> 0.54176589
A39: ORD-2024-599522 | B39: 45401 | C39: 45418 | D39: =DATEDIF(B39,C39, "MD") -> 17 | E39: =TEXT(Data!B39,"MMM-YYYY") -> Apr-2024 | F39: ="Q"&ROUNDUP(MONTH(B39)/3,0)&"-"&YEAR(B39) -> Q2-2024 | G39: Africa | H39: Nigeria | I39: Port Harcourt | J39: Non-Profit | K39: Online | L39: A. Patel | M39: Printers | N39: PRN-7303 | O39: 865.33 | P39: =IF(Q39<50, "Low", IF(Q39<200, "Medium", "High")) -> High | Q39: 1395.64 | R39: 0.175 | S39: 13 | T39: =(Q65*S39)*(1-R39) -> 8106.7057 | U39: =(O39*S39) -> 11249.29 | V39: =(T39-U39) -> -3142.5843 | W39: =IF(T39=0, 0, V39/T39) -> -0.38765244
A40: ORD-2023-651638 | B40: 45094 | C40: 45101 | D40: =DATEDIF(B40,C40, "MD") -> 7 | E40: =TEXT(Data!B40,"MMM-YYYY") -> Jun-2023 | F40: ="Q"&ROUNDUP(MONTH(B40)/3,0)&"-"&YEAR(B40) -> Q2-2023 | G40: Americas | H40: USA | I40: San Francisco | J40: Corporate | K40: Retail | L40: I. Johnson | M40: Printers | N40: PRN-6536 | O40: 313.99 | P40: =IF(Q40<50, "Low", IF(Q40<200, "Medium", "High")) -> High | Q40: 454.42 | R40: 0.129 | S40: 9 | T40: =(Q66*S40)*(1-R40) -> 8980.9071 | U40: =(O40*S40) -> 2825.91 | V40: =(T40-U40) -> 6154.9971 | W40: =IF(T40=0, 0, V40/T40) -> 0.68534248
...

Sheet Part A
A3: 1 | B3: Month
A5: 2 | B5: Quarter | C5: ="Q"&ROUNDUP(MONTH(Data!B2)/3,0)&"-"&YEAR(Data!B2) -> Q4-2024
A7: 3 | B7: Region Hierachy
A9: 4 | B9: Product Category
A11: 5 | B11: Derived Price Band

Sheet Standardised Dimension Table
A1: OrderDate | B1: Month | C1: Quarter | D1: Region | E1: Country | F1: City | G1: ProductCategory | H1: Price Band | I1: UnitPrice
A2: 45362 | B2: =TEXT(Data!B2,"MMM-YYYY") -> Oct-2024 | C2: ="Q"&ROUNDUP(MONTH(A2)/3,0)&"-"&YEAR(A2) -> Q1-2024 | D2: Africa | E2: Kenya | F2: Kisumu | G2: Components | H2: =IF(I2<50, "Low", IF(I2<200, "Medium", "High")) -> High | I2: 608.9
A3: 45363 | B3: =TEXT(Data!B3,"MMM-YYYY") -> Feb-2023 | C3: ="Q"&ROUNDUP(MONTH(A3)/3,0)&"-"&YEAR(A3) -> Q1-2024 | D3: Africa | E3: Nigeria | F3: Port Harcourt | G3: Printers | H3: =IF(I3<50, "Low", IF(I3<200, "Medium", "High")) -> High | I3: 759.33
A4: 45364 | B4: =TEXT(Data!B4,"MMM-YYYY") -> Mar-2025 | C4: ="Q"&ROUNDUP(MONTH(A4)/3,0)&"-"&YEAR(A4) -> Q1-2024 | D4: Africa | E4: Kenya | F4: Nairobi | G4: Networking | H4: =IF(I4<50, "Low", IF(I4<200, "Medium", "High")) -> Low | I4: -30.66
A5: 45365 | B5: =TEXT(Data!B5,"MMM-YYYY") -> Dec-2023 | C5: ="Q"&ROUNDUP(MONTH(A5)/3,0)&"-"&YEAR(A5) -> Q1-2024 | D5: Africa | E5: Nigeria | F5: Lagos | G5: Phones | H5: =IF(I5<50, "Low", IF(I5<200, "Medium", "High")) -> High | I5: 255.94
A6: 45366 | B6: =TEXT(Data!B6,"MMM-YYYY") -> Jan-2023 | C6: ="Q"&ROUNDUP(MONTH(A6)/3,0)&"-"&YEAR(A6) -> Q1-2024 | D6: Asia | E6: Japan | F6: Osaka | G6: Printers | H6: =IF(I6<50, "Low", IF(I6<200, "Medium", "High")) -> High | I6: 813.51
A7: 45367 | B7: =TEXT(Data!B7,"MMM-YYYY") -> Dec-2024 | C7: ="Q"&ROUNDUP(MONTH(A7)/3,0)&"-"&YEAR(A7) -> Q1-2024 | D7: Americas | E7: Canada | F7: Toronto | G7: Laptops | H7: =IF(I7<50, "Low", IF(I7<200, "Medium", "High")) -> High | I7: 591.68
A8: 45368 | B8: =TEXT(Data!B8,"MMM-YYYY") -> Jan-2023 | C8: ="Q"&ROUNDUP(MONTH(A8)/3,0)&"-"&YEAR(A8) -> Q1-2024 | D8: Asia | E8: India | F8: Bengaluru | G8: Monitors | H8: =IF(I8<50, "Low", IF(I8<200, "Medium", "High")) -> High | I8: 845.97
A9: 45369 | B9: =TEXT(Data!B9,"MMM-YYYY") -> May-2024 | C9: ="Q"&ROUNDUP(MONTH(A9)/3,0)&"-"&YEAR(A9) -> Q1-2024 | D9: Africa | E9: Nigeria | F9: Abuja | G9: Printers | H9: =IF(I9<50, "Low", IF(I9<200, "Medium", "High")) -> Low | I9: 47.22
A10: 45370 | B10: =TEXT(Data!B10,"MMM-YYYY") -> May-2025 | C10: ="Q"&ROUNDUP(MONTH(A10)/3,0)&"-"&YEAR(A10) -> Q1-2024 | D10: Africa | E10: Nigeria | F10: Abuja | G10: Monitors | H10: =IF(I10<50, "Low", IF(I10<200, "Medium", "High")) -> High | I10: 2530.81
A11: 45371 | B11: =TEXT(Data!B11,"MMM-YYYY") -> Jan-2024 | C11: ="Q"&ROUNDUP(MONTH(A11)/3,0)&"-"&YEAR(A11) -> Q1-2024 | D11: Americas | E11: Brazil | F11: São Paulo | G11: Components | H11: =IF(I11<50, "Low", IF(I11<200, "Medium", "High")) -> High | I11: 2309.56
A12: 45372 | B12: =TEXT(Data!B12,"MMM-YYYY") -> Jan-2025 | C12: ="Q"&ROUNDUP(MONTH(A12)/3,0)&"-"&YEAR(A12) -> Q1-2024 | D12: Europe | E12: Germany | F12: Berlin | G12: Accessories | H12: =IF(I12<50, "Low", IF(I12<200, "Medium", "High")) -> High | I12: 700.12
A13: 45373 | B13: =TEXT(Data!B13,"MMM-YYYY") -> Mar-2025 | C13: ="Q"&ROUNDUP(MONTH(A13)/3,0)&"-"&YEAR(A13) -> Q1-2024 | D13: Asia | E13: Japan | F13: Osaka | G13: Phones | H13: =IF(I13<50, "Low", IF(I13<200, "Medium", "High")) -> High | I13: 691.37
... A633: 45993 | B633: =TEXT(Data!B633,"MMM-YYYY") -> Feb-2025 | C633: ="Q"&ROUNDUP(MONTH(A633)/3,0)&"-"&YEAR(A633) -> Q4-2025 | D633: Asia | E633: Japan | F633: Osaka | G633: Laptops | H633: =IF(I633<50, "Low", IF(I633<200, "Medium", "High")) -> Low | I633: 45.98

Sheet Analysis
A1: OrderDate | B1: Order Month | C1: Cohort Month | D1: First Sale Date | E1: Quarter | F1: Region | G1: Country | H1: City | I1: ProductCategory | J1: Price Band | K1: UnitPrice | L1: UnitPrice | M1: DiscountPct | N1: Quantity | O1: Gross Revenue
A2: 45362 | B2: =TEXT(Data!B2,"MMM-YYYY") -> Oct-2024 | C2: =TEXT(D2, "MMM-YYYY") -> Mar-2024 | D2: =_xlfn.MINIFS(A2:A2, G2:G2,G2) -> 45362 | E2: ="Q"&ROUNDUP(MONTH(A2)/3,0)&"-"&YEAR(A2) -> Q1-2024 | F2: Africa | G2: Kenya | H2: Kisumu | I2: Components | J2: =IF(K2<50, "Low", IF(K2<200, "Medium", "High")) -> High | K2: 608.9 | L2: 608.9 | M2: 0.112 | N2: 9 | O2: =(L28*N2)*(1-M2) -> 1403.9546
A3: 45363 | B3: =TEXT(Data!B3,"MMM-YYYY") -> Feb-2023 | C3: =TEXT(D3, "MMM-YYYY") -> Mar-2024 | D3: =_xlfn.MINIFS(A3:A3, G3:G3,G3) -> 45363 | E3: ="Q"&ROUNDUP(MONTH(A3)/3,0)&"-"&YEAR(A3) -> Q1-2024 | F3: Africa | G3: Nigeria | H3: Port Harcourt | I3: Printers | J3: =IF(K3<50, "Low", IF(K3<200, "Medium", "High")) -> High | K3: 759.33 | L3: 759.33 | M3: 0.237 | N3: 31 | O3: =(L29*N3)*(1-M3) -> 17934.414
A4: 45364 | B4: =TEXT(Data!B4,"MMM-YYYY") -> Mar-2025 | C4: =TEXT(D4, "MMM-YYYY") -> Mar-2024 | D4: =_xlfn.MINIFS(A4:A4, G4:G4,G4) -> 45364 | E4: ="Q"&ROUNDUP(MONTH(A4)/3,0)&"-"&YEAR(A4) -> Q1-2024 | F4: Africa | G4: Kenya | H4: Nairobi | I4: Networking | J4: =IF(K4<50, "Low", IF(K4<200, "Medium", "High")) -> Low | K4: -30.66 | L4: -30.66 | M4: 0.131 | N4: 12 | O4: =(L30*N4)*(1-M4) -> 4534.0944
A5: 45365 | B5: =TEXT(Data!B5,"MMM-YYYY") -> Dec-2023 | C5: =TEXT(D5, "MMM-YYYY") -> Mar-2024 | D5: =_xlfn.MINIFS(A5:A5, G5:G5,G5) -> 45365 | E5: ="Q"&ROUNDUP(MONTH(A5)/3,0)&"-"&YEAR(A5) -> Q1-2024 | F5: Africa | G5: Nigeria | H5: Lagos | I5: Phones | J5: =IF(K5<50, "Low", IF(K5<200, "Medium", "High")) -> High | K5: 255.94 | L5: 255.94 | M5: 0.072 | N5: 22 | O5: =(L31*N5)*(1-M5) -> 34016.731
A6: 45366 | B6: =TEXT(Data!B6,"MMM-YYYY") -> Jan-2023 | C6: =TEXT(D6, "MMM-YYYY") -> Mar-2024 | D6: =_xlfn.MINIFS(A6:A6, G6:G6,G6) -> 45366 | E6: ="Q"&ROUNDUP(MONTH(A6)/3,0)&"-"&YEAR(A6) -> Q1-2024 | F6: Asia | G6: Japan | H6: Osaka | I6: Printers | J6: =IF(K6<50, "Low", IF(K6<200, "Medium", "High")) -> High | K6: 813.51 | L6: 813.51 | M6: 0.102 | N6: 15 | O6: =(L32*N6)*(1-M6) -> 8510.0766
A7: 45367 | B7: =TEXT(Data!B7,"MMM-YYYY") -> Dec-2024 | C7: =TEXT(D7, "MMM-YYYY") -> Mar-2024 | D7: =_xlfn.MINIFS(A7:A7, G7:G7,G7) -> 45367 | E7: ="Q"&ROUNDUP(MONTH(A7)/3,0)&"-"&YEAR(A7) -> Q1-2024 | F7: Americas | G7: Canada | H7: Toronto | I7: Laptops | J7: =IF(K7<50, "Low", IF(K7<200, "Medium", "High")) -> High | K7: 591.68 | L7: 591.68 | M7: 0 | N7: 7 | O7: =(L33*N7)*(1-M7) -> 12558.49
A8: 45368 | B8: =TEXT(Data!B8,"MMM-YYYY") -> Jan-2023 | C8: =TEXT(D8, "MMM-YYYY") -> Mar-2024 | D8: =_xlfn.MINIFS(A8:A8, G8:G8,G8) -> 45368 | E8: ="Q"&ROUNDUP(MONTH(A8)/3,0)&"-"&YEAR(A8) -> Q1-2024 | F8: Asia | G8: India | H8: Bengaluru | I8: Monitors | J8: =IF(K8<50, "Low", IF(K8<200, "Medium", "High")) -> High | K8: 845.97 | L8: 845.97 | M8: 0.147 | N8: 4 | O8: =(L34*N8)*(1-M8) -> 8983.8642
A9: 45369 | B9: =TEXT(Data!B9,"MMM-YYYY") -> May-2024 | C9: =TEXT(D9, "MMM-YYYY") -> Mar-2024 | D9: =_xlfn.MINIFS(A9:A9, G9:G9,G9) -> 45369 | E9: ="Q"&ROUNDUP(MONTH(A9)/3,0)&"-"&YEAR(A9) -> Q1-2024 | F9: Africa | G9: Nigeria | H9: Abuja | I9: Printers | J9: =IF(K9<50, "Low", IF(K9<200, "Medium", "High")) -> Low | K9: 47.22 | L9: 47.22 | M9: 0.194 | N9: 18 | O9: =(L35*N9)*(1-M9) -> 19177.4
A10: 45370 | B10: =TEXT(Data!B10,"MMM-YYYY") -> May-2025 | C10: =TEXT(D10, "MMM-YYYY") -> Mar-2024 | D10: =_xlfn.MINIFS(A10:A10, G10:G10,G10) -> 45370 | E10: ="Q"&ROUNDUP(MONTH(A10)/3,0)&"-"&YEAR(A10) -> Q1-2024 | F10: Africa | G10: Nigeria | H10: Abuja | I10: Monitors | J10: =IF(K10<50, "Low", IF(K10<200, "Medium", "High")) -> High | K10: 2530.81 | L10: 2530.81 | M10: 0.031 | N10: 6 | O10: =(L36*N10)*(1-M10) -> 17656.362
A11: 45371 | B11: =TEXT(Data!B11,"MMM-YYYY") -> Jan-2024 | C11: =TEXT(D11, "MMM-YYYY") -> Mar-2024 | D11: =_xlfn.MINIFS(A11:A11, G11:G11,G11) -> 45371 | E11: ="Q"&ROUNDUP(MONTH(A11)/3,0)&"-"&YEAR(A11) -> Q1-2024 | F11: Americas | G11: Brazil | H11: São Paulo | I11: Components | J11: =IF(K11<50, "Low", IF(K11<200, "Medium", "High")) -> High | K11: 2309.56 | L11: 2309.56 | M11: 0.149 | N11: 31 | O11: =(L37*N11)*(1-M11) -> 5259.58
A12: 45372 | B12: =TEXT(Data!B12,"MMM-YYYY") -> Jan-2025 | C12: =TEXT(D12, "MMM-YYYY") -> Mar-2024 | D12: =_xlfn.MINIFS(A12:A12, G12:G12,G12) -> 45372 | E12: ="Q"&ROUNDUP(MONTH(A12)/3,0)&"-"&YEAR(A12) -> Q1-2024 | F12: Europe | G12: Germany | H12: Berlin | I12: Accessories | J12: =IF(K12<50, "Low", IF(K12<200, "Medium", "High")) -> High | K12: 700.12 | L12: 700.12 | M12: 0.006 | N12: 23 | O12: =(L38*N12)*(1-M12) -> 21204.734
A13: 45373 | B13: =TEXT(Data!B13,"MMM-YYYY") -> Mar-2025 | C13: =TEXT(D13, "MMM-YYYY") -> Mar-2024 | D13: =_xlfn.MINIFS(A13:A13, G13:G13,G13) -> 45373 | E13: ="Q"&ROUNDUP(MONTH(A13)/3,0)&"-"&YEAR(A13) -> Q1-2024 | F13: Asia | G13: Japan | H13: Osaka | I13: Phones | J13: =IF(K13<50, "Low", IF(K13<200, "Medium", "High")) -> High | K13: 691.37 | L13: 691.37 | M13: 0.25 | N13: 20 | O13: =(L39*N13)*(1-M13) -> 26031.15
... A633: 45993 | B633: =TEXT(Data!B633,"MMM-YYYY") -> Feb-2025 | C633: =TEXT(D633, "MMM-YYYY") -> Dec-2025 | D633: =_xlfn.MINIFS(A633:A633, G633:G633,G633) -> 45993 | E633: ="Q"&ROUNDUP(MONTH(A633)/3,0)&"-"&YEAR(A633) -> Q4-2025 | F633: Asia | G633: Japan | H633: Osaka | I633: Laptops | J633: =IF(K633<50, "Low", IF(K633<200, "Medium", "High")) -> Low | K633: 45.98 | L633: 45.98 | M633: 0.173 | N633: 7 | O633: =(L659*N633)*(1-M633) -> 0

Sheet Pivot Cohort Analysis
A1: Country | B1: (All)
A3: Sum of Gross Revenue | B3: Column Labels
A4: Row Labels | B4: Apr-2023 | C4: Apr-2024 | D4: Apr-2025 | E4: Aug-2023 | F4: Aug-2024 | G4: Aug-2025 | H4: Dec-2023 | I4: Dec-2024 | J4: Feb-2023 | K4: Feb-2024 | L4: Feb-2025 | M4: Jan-2023 | N4: Jan-2024 | O4: Jan-2025 | P4: Jul-2023 | Q4: Jul-2024 | R4: Jul-2025 | S4: Jun-2023 | T4: Jun-2024 | U4: Jun-2025 | V4: Mar-2023 | W4: Mar-2024 | X4: Mar-2025 | Y4: May-2023 | Z4: May-2024 | AA4: May-2025 | AB4: Nov-2023 | AC4: Nov-2024 | AD4: Oct-2023 | AE4: Oct-2024 | AF4: Sept-2023 | AG4: Sept-2024 | AH4: Sept-2025 | AI4: Grand Total
A5: Apr-2024 | B5: 14824.899 | C5: 22477.306 | D5: 11781.339 | F5: 49294.844 | I5: 43367.692 | J5: 41567.724 | N5: 7368.06 | P5: 21312.892 | Q5: 1243.5675 | R5: -19.30928 | S5: 27907.737 | T5: 353.7664 | U5: 29284.637 | V5: 86276.904 | W5: 25427.751 | Y5: 24160.544 | Z5: 53971.103 | AA5: 17662.129 | AC5: 21665.382 | AE5: 32079.351 | AI5: 532008.32
A6: Apr-2025 | D6: 26377.533 | E6: 6993.862 | F6: 30066.425 | G6: 51745.06 | H6: 10899.6 | I6: 22741.536 | L6: 15273.33 | O6: 11831.256 | Q6: 9079.5053 | T6: 22569.276 | U6: 9830.4128 | V6: 20289.09 | W6: 5499.1688 | X6: 1687.789 | Y6: 11663.267 | Z6: 41010.924 | AA6: 47770.043 | AC6: 5658.8054 | AD6: 31288.406 | AF6: 44766.472 | AG6: 18353.975 | AH6: 14660.4 | AI6: 460056.14
A7: Aug-2024 | B7: 32735.194 | C7: 45741.466 | D7: 26608.919 | F7: 57488.471 | G7: 10180.661 | H7: 2454.4138 | J7: 97289.67 | K7: 15076 | L7: 7100.6852 | P7: 31848.367 | Q7: 18676.975 | T7: 13928.655 | V7: 50207.703 | Z7: 5308.1555 | AA7: 36583.531 | AB7: 42353.883 | AD7: 1815.2109 | AE7: 14878.791 | AF7: 8757.7692 | AG7: 57712.05 | AH7: 49.7802 | AI7: 576796.35
A8: Aug-2025 | B8: 25448.667 | C8: 17160.811 | D8: 11813.082 | E8: 44990.513 | F8: 31548.788 | G8: 30771.51 | L8: 36886.576 | M8: 7653.6 | N8: 30255.496 | O8: 9162.3608 | P8: 32372.731 | Q8: 33964.937 | S8: 11222.702 | T8: 53128.408 | U8: 9059.1936 | W8: 28098.684 | X8: 8687.4149 | Y8: 62896.528 | Z8: 6873.6311 | AA8: 5994.1018 | AC8: 6953.9874 | AE8: 40152.023 | AF8: 50294.071 | AI8: 595389.82
A9: Dec-2024 | D9: 30054.984 | E9: 28032.604 | G9: 7371.4889 | H9: 15054.2 | L9: 6753.7725 | N9: 79337.233 | P9: 17447.837 | S9: 16255.516 | T9: 8039.3544 | U9: 9349.0342 | W9: 99322.511 | X9: 13554.149 | Y9: 3736.312 | AA9: 8208.8609 | AD9: 3444.5591 | AE9: 32644.137 | AG9: 11640.573 | AH9: 1617.8812 | AI9: 391865.01
A10: Dec-2025 | L10: 0 | AB10: 0 | AI10: 0
A11: Feb-2025 | B11: 36385.454 | C11: 2362.551 | D11: 7038.4882 | E11: 2377.9312 | F11: 31286.996 | H11: 79516.988 | J11: 19625.658 | K11: 34122.605 | O11: 27369.283 | P11: 79487.856 | Q11: 106718.6 | S11: 5667.8292 | U11: 6418.5449 | Y11: 3760.95 | AA11: 841.5672 | AB11: 6720.9426 | AC11: 4722.4032 | AD11: 11668.448 | AE11: 33921.8 | AH11: 21779.835 | AI11: 521794.73
A12: Jan-2025 | D12: 9947.2987 | I12: 13444.762 | J12: 24902.263 | K12: 24630.102 | M12: 35096.967 | N12: 8113.3334 | O12: 47441.619 | P12: 18252.955 | S12: 6452.9218 | T12: 13585.841 | U12: 26888.394 | V12: 125232.05 | W12: 68306.553 | X12: 52560.144 | Y12: 45984.888 | Z12: 39089.558 | AA12: 18720.941 | AB12: 27971.861 | AC12: 35911.89 | AD12: 10311.924 | AG12: 4829.1858 | AI12: 657675.45
A13: Jul-2024 | B13: 14342.188 | E13: 20235.176 | G13: 40507.245 | H13: 7009.2643 | I13: 62986.847 | K13: 35027.455 | L13: 10997.906 | M13: 33178.341 | O13: 17422.405 | P13: 27251.1 | R13: 4225.1933 | S13: 9278.4804 | T13: 44519.542 | U13: 38245.205 | V13: 9902.9228 | X13: 15583.459 | Y13: 15179.749 | Z13: 9877.511 | AB13: 21486.142 | AC13: 47159.894 | AI13: 484416.03
A14: Jul-2025 | B14: 31378.532 | C14: 21447.614 | D14: 20815.888 | E14: 9504.8997 | F14: 20669.092 | G14: 5660.0544 | I14: 6964.3963 | J14: 10393.181 | N14: 24019.121 | P14: 20043.768 | R14: 16395.612 | S14: 10084.108 | V14: 22462.452 | W14: 2603.4792 | X14: 23976.759 | Y14: 2493.1507 | Z14: 97889.28 | AA14: 3415.8504 | AC14: 14894.108 | AD14: 29896.224 | AE14: 7506.8196 | AG14: 160976.27 | AH14: 8401.894 | AI14: 571892.55
A15: Jun-2024 | B15: 47694.762 | C15: 36.9702 | D15: 4544.8392 | F15: 5654.2295 | G15: 9137.6141 | H15: 18364.589 | I15: 24706.764 | J15: 8854.2763 | N15: 3521.1077 | O15: 31422.63 | R15: 3615.6742 | S15: 30168.894 | T15: 54227.522 | U15: 74251.58 | X15: 14467.482 | Y15: 22483.549 | Z15: 29865.732 | AA15: 2281.3896 | AE15: 7561.2927 | AG15: 4270.2181 | AH15: 9873.8136 | AI15: 407004.93
A16: Jun-2025 | D16: 31644.291 | E16: 19353.546 | G16: 13790.976 | H16: 116731.22 | I16: 674.07536 | K16: 8549.7652 | M16: 3365.5756 | P16: 6140.8031 | R16: 13652.986 | T16: 46314.986 | U16: 19287.106 | W16: 733.0112 | X16: 40309.208 | Y16: 129059.84 | Z16: 39751.9 | AB16: 35310.319 | AC16: 21031.9 | AI16: 545701.51
A17: Mar-2024 | B17: 14666.09 | H17: 8510.0766 | I17: 88929.73 | J17: 4534.0944 | M17: 31735.89 | N17: 28021.034 | O17: 26031.15 | Q17: 3565.5894 | R17: 15979.622 | W17: 1403.9546 | X17: 46661.229 | Z17: 17656.362 | AA17: 30794.86 | AE17: 17934.414 | AH17: 33813.981 | AI17: 370238.08
A18: Mar-2025 | B18: 59066.056 | C18: 28646.703 | D18: 26958.519 | G18: 42205.544 | H18: 17698.503 | J18: 15891.92 | L18: 35734.359 | N18: 28945.64 | O18: 41965.13 | P18: 45086.595 | Q18: 14867.19 | R18: 13660.278 | S18: 98011.346 | T18: 26511.737 | U18: 54798.866 | V18: 11379.122 | W18: 35913.938 | X18: 23605.161 | Y18: 20697.169 | Z18: 11597.651 | AC18: 4499.15 | AF18: 12985.618 | AI18: 670726.2
A19: May-2024 | B19: 11803.702 | C19: 5807.6003 | D19: 78030.317 | E19: 57129.954 | F19: 21984.96 | H19: 9671.5258 | I19: 34632.216 | J19: 45029.794 | L19: 4119.0446 | O19: 21238.118 | S19: 44117.408 | T19: 3822.367 | U19: 93667.868 | V19: 28786.488 | W19: 29809.479 | Y19: 10198.972 | Z19: 11273.617 | AA19: 4086.5862 | AC19: 6580.1227 | AE19: 11819.917 | AF19: 2073.2046 | AH19: 7255.458 | AI19: 542938.72
A20: May-2025 | B20: 989.3947 | F20: 39489.654 | G20: 33475.68 | H20: 22309.837 | I20: 59221.441 | J20: 15339.646 | K20: 105981.7 | L20: 1853.3248 | N20: 5749.1559 | R20: 78253.279 | S20: 7167.5669 | U20: 1948.1462 | W20: 48582.216 | X20: 4846.6447 | Y20: 5497.3325 | AA20: 41071.932 | AC20: 45872.984 | AD20: 17009.912 | AF20: 20287.469 | AG20: 21303.28 | AH20: 20866.56 | AI20: 597117.16
A21: Nov-2024 | B21: 7944.7971 | C21: 39508.724 | D21: 51929.129 | E21: 12481.437 | G21: 9431.7696 | I21: 5532.6686 | K21: 6352.3799 | N21: 31218.691 | Q21: 29033.704 | R21: 5002.3123 | U21: 15357.7 | V21: 17084.938 | W21: 74491.455 | Y21: 17985.918 | AA21: 17830.455 | AB21: 15275.596 | AC21: 2237.6024 | AD21: 10855.106 | AE21: 18599.828 | AF21: 18307.712 | AG21: 48863.066 | AH21: 11792.958 | AI21: 467117.95
A22: Nov-2025 | B22: 10511.386 | D22: 0 | E22: 0 | F22: 3208.8336 | G22: 2667.2333 | H22: 0 | I22: 0 | K22: 0 | N22: 0 | P22: 0 | Q22: 0 | R22: 0 | S22: 0 | T22: 0 | U22: 0 | W22: 18416.457 | X22: 0 | AA22: 34640.985 | AB22: 0 | AC22: 0 | AD22: 0 | AE22: 0 | AF22: 486.56036 | AI22: 69931.455
A23: Oct-2024 | B23: 24416.279 | D23: 4648.9351 | E23: 9151.63 | G23: 31629.555 | H23: 18916.432 | K23: 64128.859 | L23: 554.9796 | M23: 789.46368 | O23: 6823.2037 | P23: 20805.371 | R23: 87186.76 | V23: 32095.464 | Y23: 34932.682 | AB23: 6137.9842 | AD23: 6770.0719 | AE23: 25491.118 | AF23: 158.1652 | AG23: 36310.302 | AI23: 410947.25
A24: Oct-2025 | B24: 19117.733 | D24: 51926.012 | E24: 109937.12 | F24: 62066.492 | G24: 7543.8006 | H24: 28925.557 | J24: 24128.643 | K24: 21446.4 | L24: 17843.722 | M24: 8582.88 | N24: 6980.1763 | Q24: 4083.43 | R24: 20722.293 | S24: 19816.344 | T24: 66005.5 | U24: 4921.3008 | W24: 46878.839 | X24: 31581.442 | Y24: 3085.38 | AC24: 8728.9427 | AG24: 2183.9423 | AI24: 566505.95
A25: Sept-2024 | B25: 85336.721 | D25: 17694.882 | E25: 61980.597 | F25: 13882.919 | G25: 26302.967 | K25: 74200.581 | L25: 7256.5422 | M25: 132103 | N25: 11002.005 | O25: 6319.9847 | P25: 9587.7281 | S25: 1541.592 | Y25: 14139.906 | Z25: 9097.8674 | AD25: 5219.7773 | AE25: 101008.89 | AG25: 3645.6089 | AH25: 593.5216 | AI25: 580915.09
A26: Sept-2025 | B26: 11393.723 | F26: 23507.575 | G26: 9301.946 | H26: 35256.783 | I26: 10814.319 | J26: 39068.86 | K26: 26490.276 | L26: 20641.897 | M26: 14063.654 | N26: 5968.5956 | P26: 18398.439 | Q26: 1119.492 | T26: 25485.5 | U26: 29597.64 | V26: 10310.463 | W26: 8118.5574 | Y26: 1551.6 | Z26: 8897.573 | AA26: 58944.55 | AC26: 64527.264 | AE26: 22209.694 | AF26: 4778.8646 | AI26: 450447.26
A27: Grand Total | B27: 448055.58 | C27: 183189.75 | D27: 411814.46 | E27: 382169.27 | F27: 390149.28 | G27: 331723.1 | H27: 391318.99 | I27: 374016.45 | J27: 346625.73 | K27: 416006.13 | L27: 165016.14 | M27: 266569.37 | N27: 270499.65 | O27: 247027.14 | P27: 348036.44 | Q27: 222352.99 | R27: 258674.7 | S27: 287692.45 | T27: 378492.45 | U27: 422905.63 | V27: 414027.6 | W27: 493606.05 | X27: 277520.88 | Y27: 429507.73 | Z27: 382160.86 | AA27: 328847.78 | AB27: 155256.73 | AC27: 290444.44 | AD27: 128279.64 | AE27: 365808.07 | AF27: 162895.91 | AG27: 370088.47 | AH27: 130706.08 | AI27: 10471486

Sheet ABC Data
A1: ORD-2024-275203 | B1: 45362 | C1: 45388 | D1: =DATEDIF(B1,C1, "MD") -> 26 | E1: =TEXT(Data!B1,"MMM-YYYY") -> Mar-2024 | F1: ="Q"&ROUNDUP(MONTH(B1)/3,0)&"-"&YEAR(B1) -> Q1-2024 | G1: Africa | H1: Kenya | I1: Kisumu | J1: Corporate | K1: Retail | L1: C. Otieno | M1: Components | N1: CMP-8270 | O1: 279.24 | P1: =IF(Q1<50, "Low", IF(Q1<200, "Medium", "High")) -> High | Q1: 608.9 | R1: 0.112 | S1: 9 | T1: =(Q27*S1)*(1-R1) -> 1403.9546 | U1: =(O1*S1) -> 2513.16 | V1: =(T1-U1) -> -1109.2054 | W1: =IF(T1=0, 0, V1/T1) -> -0.79005783
A2: ORD-2024-358795 | B2: 45588 | C2: 45587 | D2: =DATEDIF(C2, B2, "MD") -> 1 | E2: =TEXT(Data!B2,"MMM-YYYY") -> Oct-2024 | F2: ="Q"&ROUNDUP(MONTH(B2)/3,0)&"-"&YEAR(B2) -> Q4-2024 | G2: Africa | H2: Nigeria | I2: Port Harcourt | J2: Education | K2: Online | L2: J. Njeri | M2: Printers | N2: PRN-9322 | O2: 1084.39 | P2: =IF(Q2<50, "Low", IF(Q2<200, "Medium", "High")) -> High | Q2: 759.33 | R2: 0.237 | S2: 31 | T2: =(Q28*S2)*(1-R2) -> 17934.414 | U2: =(O2*S2) -> 33616.09 | V2: =(T2-U2) -> -15681.676 | W2: =IF(T2=0, 0, V2/T2) -> -0.87439019
A3: ORD-2023-373538 | B3: 44985 | C3: 45010 | D3: =DATEDIF(B3,C3, "MD") -> 25 | E3: =TEXT(Data!B3,"MMM-YYYY") -> Feb-2023 | F3: ="Q"&ROUNDUP(MONTH(B3)/3,0)&"-"&YEAR(B3) -> Q1-2023 | G3: Africa | H3: Kenya | I3: Nairobi | J3: Corporate | K3: Retail | L3: I. Johnson | M3: Networking | N3: NET-9666 | O3: 1460.76 | P3: =IF(Q3<50, "Low", IF(Q3<200, "Medium", "High")) -> Low | Q3: -30.66 | R3: 0.131 | S3: 12 | T3: =(Q29*S3)*(1-R3) -> 4534.0944 | U3: =(O3*S3) -> 17529.12 | V3: =(T3-U3) -> -12995.026 | W3: =IF(T3=0, 0, V3/T3) -> -2.8660686
A4: ORD-2025-168148 | B4: 45745 | C4: 45749 | D4: =DATEDIF(B4,C4, "MD") -> 4 | E4: =TEXT(Data!B4,"MMM-YYYY") -> Mar-2025 | F4: ="Q"&ROUNDUP(MONTH(B4)/3,0)&"-"&YEAR(B4) -> Q1-2025 | G4: Africa | H4: Nigeria | I4: Lagos | J4: Non-Profit | K4: Marketplace | L4: G. Dubois | M4: Phones | N4: PHN-4556 | O4: 259.93 | P4: =IF(Q4<50, "Low", IF(Q4<200, "Medium", "High")) -> High | Q4: 255.94 | R4: 0.072 | S4: 22 | T4: =(Q30*S4)*(1-R4) -> 34016.731 | U4: =(O4*S4) -> 5718.46 | V4: =(T4-U4) -> 28298.271 | W4: =IF(T4=0, 0, V4/T4) -> 0.83189272
A5: ORD-2023-824839 | B5: 45266 | C5: 45291 | D5: =DATEDIF(B5,C5, "MD") -> 25 | E5: =TEXT(Data!B5,"MMM-YYYY") -> Dec-2023 | F5: ="Q"&ROUNDUP(MONTH(B5)/3,0)&"-"&YEAR(B5) -> Q4-2023 | G5: Asia | H5: Japan | I5: Osaka | J5: Consumer | K5: Retail | L5: L. Okafor | M5: Printers | N5: PRN-8041 | O5: 663.03 | P5: =IF(Q5<50, "Low", IF(Q5<200, "Medium", "High")) -> High | Q5: 813.51 | R5: 0.102 | S5: 15 | T5: =(Q31*S5)*(1-R5) -> 8510.0766 | U5: =(O5*S5) -> 9945.45 | V5: =(T5-U5) -> -1435.3734 | W5: =IF(T5=0, 0, V5/T5) -> -0.16866751
A6: ORD-2023-723587 | B6: 44928 | C6: 44931 | D6: =DATEDIF(B6,C6, "MD") -> 3 | E6: =TEXT(Data!B6,"MMM-YYYY") -> Jan-2023 | F6: ="Q"&ROUNDUP(MONTH(B6)/3,0)&"-"&YEAR(B6) -> Q1-2023 | G6: Americas | H6: Canada | I6: Toronto | J6: Corporate | K6: Distributor | L6: B. Chen | M6: Laptops | N6: LAP-8555 | O6: 315.87 | P6: =IF(Q6<50, "Low", IF(Q6<200, "Medium", "High")) -> High | Q6: 591.68 | R6: 0 | S6: 7 | T6: =(Q32*S6)*(1-R6) -> 12558.49 | U6: =(O6*S6) -> 2211.09 | V6: =(T6-U6) -> 10347.4 | W6: =IF(T6=0, 0, V6/T6) -> 0.82393664
A7: ORD-2024-336584 | B7: 45653 | C7: 45671 | D7: =DATEDIF(B7,C7, "MD") -> 18 | E7: =TEXT(Data!B7,"MMM-YYYY") -> Dec-2024 | F7: ="Q"&ROUNDUP(MONTH(B7)/3,0)&"-"&YEAR(B7) -> Q4-2024 | G7: Asia | H7: India | I7: Bengaluru | J7: Small Business | K7: Marketplace | L7: E. Garcia | M7: Monitors | N7: MON-8629 | O7: 586.07 | P7: =IF(Q7<50, "Low", IF(Q7<200, "Medium", "High")) -> High | Q7: 845.97 | R7: 0.147 | S7: 4 | T7: =(Q33*S7)*(1-R7) -> 8983.8642 | U7: =(O7*S7) -> 2344.28 | V7: =(T7-U7) -> 6639.5842 | W7: =IF(T7=0, 0, V7/T7) -> 0.73905661
A8: ORD-2023-112666 | B8: 44941 | C8: 44939 | D8: =DATEDIF(C8,B8, "MD") -> 2 | E8: =TEXT(Data!B8,"MMM-YYYY") -> Jan-2023 | F8: ="Q"&ROUNDUP(MONTH(B8)/3,0)&"-"&YEAR(B8) -> Q1-2023 | G8: Africa | H8: Nigeria | I8: Abuja | J8: Education | K8: Online | L8: O. Wang | M8: Printers | N8: PRN-6276 | O8: 28.38 | P8: =IF(Q8<50, "Low", IF(Q8<200, "Medium", "High")) -> Low | Q8: 47.22 | R8: 0.194 | S8: 18 | T8: =(Q34*S8)*(1-R8) -> 19177.4 | U8: =(O8*S8) -> 510.84 | V8: =(T8-U8) -> 18666.56 | W8: =IF(T8=0, 0, V8/T8) -> 0.9733624
A9: ORD-2024-589570 | B9: 45416 | C9: 45441 | D9: =DATEDIF(B9,C9, "MD") -> 25 | E9: =TEXT(Data!B9,"MMM-YYYY") -> May-2024 | F9: ="Q"&ROUNDUP(MONTH(B9)/3,0)&"-"&YEAR(B9) -> Q2-2024 | G9: Africa | H9: Nigeria | I9: Abuja | J9: Non-Profit | K9: Marketplace | L9: O. Wang | M9: Monitors | N9: MON-6892 | O9: 1295.34 | P9: =IF(Q9<50, "Low", IF(Q9<200, "Medium", "High")) -> High | Q9: 2530.81 | R9: 0.031 | S9: 6 | T9: =(Q35*S9)*(1-R9) -> 17656.362 | U9: =(O9*S9) -> 7772.04 | V9: =(T9-U9) -> 9884.3222 | W9: =IF(T9=0, 0, V9/T9) -> 0.55981646
A10: ORD-2025-997421 | B10: 45798 | C10: 45817 | D10: =DATEDIF(B10,C10, "MD") -> 19 | E10: =TEXT(Data!B10,"MMM-YYYY") -> May-2025 | F10: ="Q"&ROUNDUP(MONTH(B10)/3,0)&"-"&YEAR(B10) -> Q2-2025 | G10: Americas | H10: Brazil | I10: São Paulo | J10: Non-Profit | K10: Online | L10: A. Patel | M10: Components | N10: CMP-3731 | O10: 1331.38 | P10: =IF(Q10<50, "Low", IF(Q10<200, "Medium", "High")) -> High | Q10: 2309.56 | R10: 0.149 | S10: 31 | T10: =(Q36*S10)*(1-R10) -> 5259.58 | U10: =(O10*S10) -> 41272.78 | V10: =(T10-U10) -> -36013.2 | W10: =IF(T10=0, 0, V10/T10) -> -6.8471627
A11: ORD-2024-210687 | B11: 45319 | C11: 45331 | D11: =DATEDIF(B11,C11, "MD") -> 12 | E11: =TEXT(Data!B11,"MMM-YYYY") -> Jan-2024 | F11: ="Q"&ROUNDUP(MONTH(B11)/3,0)&"-"&YEAR(B11) -> Q1-2024 | G11: Europe | H11: Germany | I11: Berlin | J11: Corporate | K11: Online | L11: G. Dubois | M11: Accessories | N11: ACC-7938 | O11: 644.17 | P11: =IF(Q11<50, "Low", IF(Q11<200, "Medium", "High")) -> High | Q11: 700.12 | R11: 0.006 | S11: 23 | T11: =(Q37*S11)*(1-R11) -> 21204.734 | U11: =(O11*S11) -> 14815.91 | V11: =(T11-U11) -> 6388.8236 | W11: =IF(T11=0, 0, V11/T11) -> 0.30129233
A12: ORD-2025-515515 | B12: 45660 | C12: 45680 | D12: =DATEDIF(B12,C12, "MD") -> 20 | E12: =TEXT(Data!B12,"MMM-YYYY") -> Jan-2025 | F12: ="Q"&ROUNDUP(MONTH(B12)/3,0)&"-"&YEAR(B12) -> Q1-2025 | G12: Asia | H12: Japan | I12: Osaka | J12: Corporate | K12: Distributor | L12: F. Müller | M12: Phones | N12: PHN-7019 | O12: 908.6 | P12: =IF(Q12<50, "Low", IF(Q12<200, "Medium", "High")) -> High | Q12: 691.37 | R12: 0.25 | S12: 20 | T12: =(Q38*S12)*(1-R12) -> 26031.15 | U12: =(O12*S12) -> 18172 | V12: =(T12-U12) -> 7859.15 | W12: =IF(T12=0, 0, V12/T12) -> 0.30191328
A13: ORD-2025-487261 | B13: 45722 | C13: 45747 | D13: =DATEDIF(B13,C13, "MD") -> 25 | E13: =TEXT(Data!B13,"MMM-YYYY") -> Mar-2025 | F13: ="Q"&ROUNDUP(MONTH(B13)/3,0)&"-"&YEAR(B13) -> Q1-2025 | G13: Americas | H13: Brazil | I13: Brasília | J13: Non-Profit | K13: Online | L13: J. Njeri | M13: Components | N13: CMP-3693 | O13: 331.57 | P13: =IF(Q13<50, "Low", IF(Q13<200, "Medium", "High")) -> High | Q13: 548.4 | R13: 0.094 | S13: 10 | T13: =(Q39*S13)*(1-R13) -> 12644.498 | U13: =(O13*S13) -> 3315.7 | V13: =(T13-U13) -> 9328.7984 | W13: =IF(T13=0, 0, V13/T13) -> 0.73777528
A14: ORD-2024-890180 | B14: 45311 | C14: 45335 | D14: =DATEDIF(B14,C14, "MD") -> 24 | E14: =TEXT(Data!B14,"MMM-YYYY") -> Jan-2024 | F14: ="Q"&ROUNDUP(MONTH(B14)/3,0)&"-"&YEAR(B14) -> Q1-2024 | G14: Europe | H14: France | I14: Marseille | J14: Corporate | K14: Retail | L14: H. Kim | M14: Printers | N14: PRN-8392 | O14: 643.53 | P14: =IF(Q14<50, "Low", IF(Q14<200, "Medium", "High")) -> High | Q14: 1439.01 | R14: 0 | S14: 15 | T14: =(Q40*S14)*(1-R14) -> 6816.3 | U14: =(O14*S14) -> 9652.95 | V14: =(T14-U14) -> -2836.65 | W14: =IF(T14=0, 0, V14/T14) -> -0.41615686
A15: ORD-2025-840976 | B15: 45901 | C15: 45930 | D15: =DATEDIF(B15,C15, "MD") -> 29 | E15: =TEXT(Data!B15,"MMM-YYYY") -> Sept-2025 | F15: ="Q"&ROUNDUP(MONTH(B15)/3,0)&"-"&YEAR(B15) -> Q3-2025 | G15: Americas | H15: Brazil | I15: Brasília | J15: Education | K15: Retail | L15: K. Singh | M15: Accessories | N15: ACC-1663 | O15: 780.59 | P15: =IF(Q15<50, "Low", IF(Q15<200, "Medium", "High")) -> High | Q15: 631.57 | R15: 0 | S15: 12 | T15: =(Q41*S15)*(1-R15) -> 18971.64 | U15: =(O15*S15) -> 9367.08 | V15: =(T15-U15) -> 9604.56 | W15: =IF(T15=0, 0, V15/T15) -> 0.50625882
A16: ORD-2023-937291 | B16: 45039 | C16: 45038 | D16: =DATEDIF(C16, B16, "MD") -> 1 | E16: =TEXT(Data!B16,"MMM-YYYY") -> Apr-2023 | F16: ="Q"&ROUNDUP(MONTH(B16)/3,0)&"-"&YEAR(B16) -> Q2-2023 | G16: Africa | H16: Kenya | I16: Nairobi | J16: Small Business | K16: Direct | L16: E. Garcia | M16: Laptops | N16: LAP-1698 | O16: 756.51 | P16: =IF(Q16<50, "Low", IF(Q16<200, "Medium", "High")) -> High | Q16: 850.8 | R16: 0.074 | S16: 9 | T16: =(Q42*S16)*(1-R16) -> 14666.09 | U16: =(O16*S16) -> 6808.59 | V16: =(T16-U16) -> 7857.4999 | W16: =IF(T16=0, 0, V16/T16) -> 0.5357597
A17: ORD-2024-206081 | B17: 45636 | C17: 45665 | D17: =DATEDIF(B17,C17, "MD") -> 29 | E17: =TEXT(Data!B17,"MMM-YYYY") -> Dec-2024 | F17: ="Q"&ROUNDUP(MONTH(B17)/3,0)&"-"&YEAR(B17) -> Q4-2024 | G17: Europe | H17: France | I17: Marseille | J17: Small Business | K17: Retail | L17: K. Singh | M17: Printers | N17: PRN-6791 | O17: 891.08 | P17: =IF(Q17<50, "Low", IF(Q17<200, "Medium", "High")) -> High | Q17: 1040.1 | R17: 0.109 | S17: 28 | T17: =(Q43*S17)*(1-R17) -> 79945.866 | U17: =(O17*S17) -> 24950.24 | V17: =(T17-U17) -> 54995.626 | W17: =IF(T17=0, 0, V17/T17) -> 0.68791082
A18: ORD-2025-233883 | B18: 45908 | C18: 45916 | D18: =DATEDIF(B18,C18, "MD") -> 8 | E18: =TEXT(Data!B18,"MMM-YYYY") -> Sept-2025 | F18: ="Q"&ROUNDUP(MONTH(B18)/3,0)&"-"&YEAR(B18) -> Q3-2025 | G18: Asia | H18: Japan | I18: Osaka | J18: Corporate | K18: Distributor | L18: C. Otieno | M18: Phones | N18: PHN-1197 | O18: 1225.57 | P18: =IF(Q18<50, "Low", IF(Q18<200, "Medium", "High")) -> High | Q18: 2705.57 | R18: 0.183 | S18: 16 | T18: =(Q44*S18)*(1-R18) -> 14842.341 | U18: =(O18*S18) -> 19609.12 | V18: =(T18-U18) -> -4766.779 | W18: =IF(T18=0, 0, V18/T18) -> -0.32116086
A19: ORD-2025-843974 | B19: 45858 | C19: 45874 | D19: =DATEDIF(B19,C19, "MD") -> 16 | E19: =TEXT(Data!B19,"MMM-YYYY") -> Jul-2025 | F19: ="Q"&ROUNDUP(MONTH(B19)/3,0)&"-"&YEAR(B19) -> Q3-2025 | G19: Americas | H19: Brazil | I19: Brasília | J19: Enterprise | K19: Marketplace | L19: G. Dubois | M19: Accessories | N19: ACC-8098 | O19: 1068.17 | P19: =IF(Q19<50, "Low", IF(Q19<200, "Medium", "High")) -> High | Q19: 2375.37 | R19: 0.109 | S19: 18 | T19: =(Q45*S19)*(1-R19) -> 15979.622 | U19: =(O19*S19) -> 19227.06 | V19: =(T19-U19) -> -3247.4383 | W19: =IF(T19=0, 0, V19/T19) -> -0.20322373
A20: ORD-2025-745263 | B20: 45798 | C20: 45796 | D20: =DATEDIF(C20,B20, "MD") -> 2 | E20: =TEXT(Data!B20,"MMM-YYYY") -> May-2025 | F20: ="Q"&ROUNDUP(MONTH(B20)/3,0)&"-"&YEAR(B20) -> Q2-2025 | G20: Europe | H20: United Kingdom | I20: Birmingham | J20: Enterprise | K20: Online | L20: M. Rossi | M20: Laptops | N20: LAP-3385 | O20: 1015.16 | P20: =IF(Q20<50, "Low", IF(Q20<200, "Medium", "High")) -> High | Q20: 2148.14 | R20: 0.038 | S20: 19 | T20: =(Q46*S20)*(1-R20) -> 25535.28 | U20: =(O20*S20) -> 19288.04 | V20: =(T20-U20) -> 6247.2399 | W20: =IF(T20=0, 0, V20/T20) -> 0.24465132
A21: ORD-2024-798002 | B21: 45498 | C21: 45497 | D21: =DATEDIF(C21,B21, "MD") -> 1 | E21: =TEXT(Data!B21,"MMM-YYYY") -> Jul-2024 | F21: ="Q"&ROUNDUP(MONTH(B21)/3,0)&"-"&YEAR(B21) -> Q3-2024 | G21: Africa | H21: Kenya | I21: Mombasa | J21: Non-Profit | K21: Direct | L21: J. Njeri | M21: Laptops | N21: LAP-9815 | O21: 1494.4 | P21: =IF(Q21<50, "Low", IF(Q21<200, "Medium", "High")) -> High | Q21: 3661.07 | R21: 0.072 | S21: 7 | T21: =(Q47*S21)*(1-R21) -> 3565.5894 | U21: =(O21*S21) -> 10460.8 | V21: =(T21-U21) -> -6895.2106 | W21: =IF(T21=0, 0, V21/T21) -> -1.9338207
A22: ORD-2023-867836 | B22: 45057 | C22: 45074 | D22: =DATEDIF(B22,C22, "MD") -> 17 | E22: =TEXT(Data!B22,"MMM-YYYY") -> May-2023 | F22: ="Q"&ROUNDUP(MONTH(B22)/3,0)&"-"&YEAR(B22) -> Q2-2023 | G22: Asia | H22: China | I22: Shenzhen | J22: Enterprise | K22: Marketplace | L22: E. Garcia | M22: Networking | N22: NET-3255 | O22: 1331.19 | P22: =IF(Q22<50, "Low", IF(Q22<200, "Medium", "High")) -> High | Q22: 2903.09 | R22: 0.143 | S22: 8 | T22: =(Q48*S22)*(1-R22) -> 24160.544 | U22: =(O22*S22) -> 10649.52 | V22: =(T22-U22) -> 13511.024 | W22: =IF(T22=0, 0, V22/T22) -> 0.55921853
A23: ORD-2025-580047 | B23: 45822 | C23: 45837 | D23: =DATEDIF(B23,C23, "MD") -> 15 | E23: =TEXT(Data!B23,"MMM-YYYY") -> Jun-2025 | F23: ="Q"&ROUNDUP(MONTH(B23)/3,0)&"-"&YEAR(B23) -> Q2-2025 | G23: Africa | H23: Nigeria | I23: Port Harcourt | J23: Consumer | K23: Marketplace | L23: M. Rossi | M23: Accessories | N23: ACC-3961 | O23: 730.99 | P23: =IF(Q23<50, "Low", IF(Q23<200, "Medium", "High")) -> High | Q23: 1242.84 | R23: 0.12 | S23: 10 | T23: =(Q49*S23)*(1-R23) -> 16065.368 | U23: =(O23*S23) -> 7309.9 | V23: =(T23-U23) -> 8755.468 | W23: =IF(T23=0, 0, V23/T23) -> 0.54499019
A24: ORD-2024-500109 | B24: 45430 | C24: 45435 | D24: =DATEDIF(B24,C24, "MD") -> 5 | E24: =TEXT(Data!B24,"MMM-YYYY") -> May-2024 | F24: ="Q"&ROUNDUP(MONTH(B24)/3,0)&"-"&YEAR(B24) -> Q2-2024 | G24: Americas | H24: USA | I24: Chicago | J24: Enterprise | K24: Retail | L24: H. Kim | M24: Laptops | N24: LAP-4987 | O24: 1274.59 | P24: =IF(Q24<50, "Low", IF(Q24<200, "Medium", "High")) -> High | Q24: 2553.69 | R24: 0.01 | S24: 8 | T24: =(Q50*S24)*(1-R24) -> 14187.65 | U24: =(O24*S24) -> 10196.72 | V24: =(T24-U24) -> 3990.9304 | W24: =IF(T24=0, 0, V24/T24) -> 0.28129608
A25: ORD-2023-271836 | B25: 44964 | C25: 44969 | D25: =DATEDIF(B25,C25, "MD") -> 5 | E25: =TEXT(Data!B25,"MMM-YYYY") -> Feb-2023 | F25: ="Q"&ROUNDUP(MONTH(B25)/3,0)&"-"&YEAR(B25) -> Q1-2023 | G25: Americas | H25: Brazil | I25: São Paulo | J25: Education | K25: Online | L25: N. Brown | M25: Components | N25: CMP-2693 | O25: 948.55 | P25: =IF(Q25<50, "Low", IF(Q25<200, "Medium", "High")) -> High | Q25: 2089.16 | R25: 0.007 | S25: 12 | T25: =(Q51*S25)*(1-R25) -> 31336.101 | U25: =(O25*S25) -> 11382.6 | V25: =(T25-U25) -> 19953.501 | W25: =IF(T25=0, 0, V25/T25) -> 0.63675762
A26: ORD-2024-215294 | B26: 45473 | C26: 45487 | D26: =DATEDIF(B26,C26, "MD") -> 14 | E26: =TEXT(Data!B26,"MMM-YYYY") -> Jun-2024 | F26: ="Q"&ROUNDUP(MONTH(B26)/3,0)&"-"&YEAR(B26) -> Q2-2024 | G26: Americas | H26: Brazil | I26: Brasília | J26: Education | K26: Retail | L26: C. Otieno | M26: Accessories | N26: ACC-8683 | O26: 1491.85 | P26: =IF(Q26<50, "Low", IF(Q26<200, "Medium", "High")) -> High | Q26: 2583.02 | R26: 0.168 | S26: 4 | T26: =(Q52*S26)*(1-R26) -> 353.7664 | U26: =(O26*S26) -> 5967.4 | V26: =(T26-U26) -> -5613.6336 | W26: =IF(T26=0, 0, V26/T26) -> -15.868193
A27: ORD-2024-788105 | B27: 45626 | C27: 45656 | D27: =DATEDIF(B27,C27, "MD") -> 0 | E27: =TEXT(Data!B27,"MMM-YYYY") -> Nov-2024 | F27: ="Q"&ROUNDUP(MONTH(B27)/3,0)&"-"&YEAR(B27) -> Q4-2024 | G27: Europe | H27: France | I27: Marseille | J27: Consumer | K27: Marketplace | L27: F. Müller | M27: Printers | N27: PRN-4170 | O27: 117.64 | P27: =IF(Q27<50, "Low", IF(Q27<200, "Medium", "High")) -> Medium | Q27: 175.67 | R27: 0 | S27: 10 | T27: =(Q53*S27)*(1-R27) -> 3857.2 | U27: =(O27*S27) -> 1176.4 | V27: =(T27-U27) -> 2680.8 | W27: =IF(T27=0, 0, V27/T27) -> 0.69501193
A28: ORD-2024-855073 | B28: 45492 | C28: 45492 | D28: =DATEDIF(B28,C28, "MD") -> 0 | E28: =TEXT(Data!B28,"MMM-YYYY") -> Jul-2024 | F28: ="Q"&ROUNDUP(MONTH(B28)/3,0)&"-"&YEAR(B28) -> Q3-2024 | G28: Africa | H28: Kenya | I28: Kisumu | J28: Small Business | K28: Retail | L28: A. Patel | M28: Phones | N28: PHN-6854 | O28: 857.24 | P28: =IF(Q28<50, "Low", IF(Q28<200, "Medium", "High")) -> High | Q28: 758.23 | R28: 0.125 | S28: 6 | T28: =(Q54*S28)*(1-R28) -> 1243.5675 | U28: =(O28*S28) -> 5143.44 | V28: =(T28-U28) -> -3899.8725 | W28: =IF(T28=0, 0, V28/T28) -> -3.136036
A29: ORD-2023-897079 | B29: 45030 | C29: 45060 | D29: =DATEDIF(B29,C29, "MD") -> 0 | E29: =TEXT(Data!B29,"MMM-YYYY") -> Apr-2023 | F29: ="Q"&ROUNDUP(MONTH(B29)/3,0)&"-"&YEAR(B29) -> Q2-2023 | G29: Africa | H29: Kenya | I29: Nakuru | J29: Consumer | K29: Marketplace | L29: M. Rossi | M29: Phones | N29: PHN-1784 | O29: 209.25 | P29: =IF(Q29<50, "Low", IF(Q29<200, "Medium", "High")) -> High | Q29: 434.8 | R29: 0 | S29: 9 | T29: =(Q55*S29)*(1-R29) -> 377.1 | U29: =(O29*S29) -> 1883.25 | V29: =(T29-U29) -> -1506.15 | W29: =IF(T29=0, 0, V29/T29) -> -3.9940334
A30: ORD-2025-548982 | B30: 45754 | C30: 45758 | D30: =DATEDIF(B30,C30, "MD") -> 4 | E30: =TEXT(Data!B30,"MMM-YYYY") -> Apr-2025 | F30: ="Q"&ROUNDUP(MONTH(B30)/3,0)&"-"&YEAR(B30) -> Q2-2025 | G30: Europe | H30: France | I30: Lyon | J30: Education | K30: Retail | L30: E. Garcia | M30: Networking | N30: NET-9716 | O30: 754.77 | P30: =IF(Q30<50, "Low", IF(Q30<200, "Medium", "High")) -> High | Q30: 1666.18 | R30: 0.139 | S30: 14 | T30: =(Q56*S30)*(1-R30) -> 11781.339 | U30: =(O30*S30) -> 10566.78 | V30: =(T30-U30) -> 1214.5585 | W30: =IF(T30=0, 0, V30/T30) -> 0.10309173
A31: ORD-2024-170313 | B31: 45653 | C31: 45672 | D31: =DATEDIF(B31,C31, "MD") -> 19 | E31: =TEXT(Data!B31,"MMM-YYYY") -> Dec-2024 | F31: ="Q"&ROUNDUP(MONTH(B31)/3,0)&"-"&YEAR(B31) -> Q4-2024 | G31: Asia | H31: India | I31: Delhi | J31: Non-Profit | K31: Distributor | L31: G. Dubois | M31: Components | N31: CMP-6919 | O31: 495.59 | P31: =IF(Q31<50, "Low", IF(Q31<200, "Medium", "High")) -> High | Q31: 631.78 | R31: 0.087 | S31: 17 | T31: =(Q57*S31)*(1-R31) -> 43367.692 | U31: =(O31*S31) -> 8425.03 | V31: =(T31-U31) -> 34942.662 | W31: =IF(T31=0, 0, V31/T31) -> 0.80573026
A32: ORD-2023-562894 | B32: 44980 | C32: 45010 | D32: =DATEDIF(B32,C32, "MD") -> 2 | E32: =TEXT(Data!B32,"MMM-YYYY") -> Feb-2023 | F32: ="Q"&ROUNDUP(MONTH(B32)/3,0)&"-"&YEAR(B32) -> Q1-2023 | G32: Americas | H32: Canada | I32: Montreal | J32: Enterprise | K32: Online | L32: D. Smith | M32: Phones | N32: PHN-4854 | O32: 1242.66 | P32: =IF(Q32<50, "Low", IF(Q32<200, "Medium", "High")) -> High | Q32: 1794.07 | R32: 0.089 | S32: 16 | T32: =(Q58*S32)*(1-R32) -> 10231.623 | U32: =(O32*S32) -> 19882.56 | V32: =(T32-U32) -> -9650.9368 | W32: =IF(T32=0, 0, V32/T32) -> -0.94324592
A33: ORD-2025-474710 | B33: 45862 | C33: 45875 | D33: =DATEDIF(B33,C33, "MD") -> 13 | E33: =TEXT(Data!B33,"MMM-YYYY") -> Jul-2025 | F33: ="Q"&ROUNDUP(MONTH(B33)/3,0)&"-"&YEAR(B33) -> Q3-2025 | G33: Africa | H33: South Africa | I33: Johannesburg | J33: Education | K33: Marketplace | L33: D. Smith | M33: Networking | N33: NET-7966 | O33: 1463.9 | P33: =IF(Q33<50, "Low", IF(Q33<200, "Medium", "High")) -> High | Q33: 2633.02 | R33: 0.084 | S33: 4 | T33: =(Q59*S33)*(1-R33) -> -19.30928 | U33: =(O33*S33) -> 5855.6 | V33: =(T33-U33) -> -5874.9093 | W33: =IF(T33=0, 0, V33/T33) -> 304.25315
